Workbook

Sheet Raw_Data
A1: Transaction_ID | B1: Date | C1: Customer_ID | D1: Customer_Name | E1: Product_ID | F1: Product_Name | G1: Category | H1: Quantity | I1: Unit_Price | J1: Payment_Method | K1: Region | L1: Customer_Segment | M1: Customer_Since | N1: Total_Amount | O1: Year | P1: Month | Q1: Month_End | R1: Days_Since_Transaction | S1: Customer_Tenure_Years | T1: Timestamp
A2: TRX0155 | B2: 45393 | C2: CUST023 | D2: Paul Baker | E2: P009 | F2: Monitor | G2: Electronics | H2: 3 | I2: 249.99 | J2: Cash | K2: Central | L2: Basic | M2: 44425 | N2: 749.97 | O2: =YEAR(B2) -> 2024 | P2: =TEXT(B2,"mmm") -> Apr | Q2: =EOMONTH(B2,0) -> 45412 | R2: =TODAY()-B2 -> 920 | S2: =DATEDIF(M2,TODAY(),"Y") -> 5 | T2: =NOW() -> 46313.675
A3: TRX0023 | B3: 45396 | C3: CUST013 | D3: Joseph Jackson | E3: P009 | F3: Monitor | G3: Electronics | H3: 3 | I3: 249.99 | J3: Credit Card | K3: Central | L3: Premium | M3: 44575 | N3: 749.97 | O3: =YEAR(B3) -> 2024 | P3: =TEXT(B3,"mmm") -> Apr | Q3: =EOMONTH(B3,0) -> 45412 | R3: =TODAY()-B3 -> 917 | S3: =DATEDIF(M3,TODAY(),"Y") -> 4 | T3: =NOW() -> 46313.675
A4: TRX0139 | B4: 45399 | C4: CUST021 | D4: Kevin Scott | E4: P005 | F4: Blender | G4: Appliances | H4: 3 | I4: 59.99 | J4: PayPal | K4: South | L4: Standard | M4: 45262 | N4: 179.97 | O4: =YEAR(B4) -> 2024 | P4: =TEXT(B4,"mmm") -> Apr | Q4: =EOMONTH(B4,0) -> 45412 | R4: =TODAY()-B4 -> 914 | S4: =DATEDIF(M4,TODAY(),"Y") -> 2 | T4: =NOW() -> 46313.675
A5: TRX0043 | B5: 45400 | C5: CUST046 | D5: Kathleen Bennett | E5: P005 | F5: Blender | G5: Appliances | H5: 3 | I5: 59.99 | J5: Cash | K5: North | L5: Premium | M5: 45114 | N5: 179.97 | O5: =YEAR(B5) -> 2024 | P5: =TEXT(B5,"mmm") -> Apr | Q5: =EOMONTH(B5,0) -> 45412 | R5: =TODAY()-B5 -> 913 | S5: =DATEDIF(M5,TODAY(),"Y") -> 3 | T5: =NOW() -> 46313.675
A6: TRX0212 | B6: 45400 | C6: CUST003 | D6: Michael Brown | E6: P008 | F6: Bookshelf | G6: Furniture | H6: 5 | I6: 149.99 | J6: Credit Card | K6: North | L6: Premium | M6: 45295 | N6: 749.95 | O6: =YEAR(B6) -> 2024 | P6: =TEXT(B6,"mmm") -> Apr | Q6: =EOMONTH(B6,0) -> 45412 | R6: =TODAY()-B6 -> 913 | S6: =DATEDIF(M6,TODAY(),"Y") -> 2 | T6: =NOW() -> 46313.675
A7: TRX0092 | B7: 45403 | C7: CUST024 | D7: Dorothy Nelson | E7: P005 | F7: Blender | G7: Appliances | H7: 2 | I7: 59.99 | J7: Cash | K7: West | L7: Standard | M7: 44746 | N7: 119.98 | O7: =YEAR(B7) -> 2024 | P7: =TEXT(B7,"mmm") -> Apr | Q7: =EOMONTH(B7,0) -> 45412 | R7: =TODAY()-B7 -> 910 | S7: =DATEDIF(M7,TODAY(),"Y") -> 4 | T7: =NOW() -> 46313.675
A8: TRX0193 | B8: 45403 | C8: CUST024 | D8: Dorothy Nelson | E8: P003 | F8: Headphones | G8: Electronics | H8: 5 | I8: 149.99 | J8: Credit Card | K8: Central | L8: Standard | M8: 44418 | N8: 749.95 | O8: =YEAR(B8) -> 2024 | P8: =TEXT(B8,"mmm") -> Apr | Q8: =EOMONTH(B8,0) -> 45412 | R8: =TODAY()-B8 -> 910 | S8: =DATEDIF(M8,TODAY(),"Y") -> 5 | T8: =NOW() -> 46313.675
A9: TRX0240 | B9: 45403 | C9: CUST017 | D9: Charles Allen | E9: P005 | F9: Blender | G9: Appliances | H9: 3 | I9: 59.99 | J9: Debit Card | K9: South | L9: Basic | M9: 45007 | N9: 179.97 | O9: =YEAR(B9) -> 2024 | P9: =TEXT(B9,"mmm") -> Apr | Q9: =EOMONTH(B9,0) -> 45412 | R9: =TODAY()-B9 -> 910 | S9: =DATEDIF(M9,TODAY(),"Y") -> 3 | T9: =NOW() -> 46313.675
A10: TRX0135 | B10: 45405 | C10: CUST009 | D10: Robert Thomas | E10: P001 | F10: Laptop | G10: Electronics | H10: 3 | I10: 899.99 | J10: PayPal | K10: East | L10: Standard | M10: 45299 | N10: 2699.97 | O10: =YEAR(B10) -> 2024 | P10: =TEXT(B10,"mmm") -> Apr | Q10: =EOMONTH(B10,0) -> 45412 | R10: =TODAY()-B10 -> 908 | S10: =DATEDIF(M10,TODAY(),"Y") -> 2 | T10: =NOW() -> 46313.675
A11: TRX0185 | B11: 45408 | C11: CUST026 | D11: Karen Hill | E11: P005 | F11: Blender | G11: Appliances | H11: 3 | I11: 59.99 | J11: Cash | K11: West | L11: Premium | M11: 45207 | N11: 179.97 | O11: =YEAR(B11) -> 2024 | P11: =TEXT(B11,"mmm") -> Apr | Q11: =EOMONTH(B11,0) -> 45412 | R11: =TODAY()-B11 -> 905 | S11: =DATEDIF(M11,TODAY(),"Y") -> 3 | T11: =NOW() -> 46313.675
A12: TRX0138 | B12: 45408 | C12: CUST022 | D12: Susan Green | E12: P008 | F12: Bookshelf | G12: Furniture | H12: 1 | I12: 149.99 | J12: Credit Card | K12: West | L12: Standard | M12: 45103 | N12: 149.99 | O12: =YEAR(B12) -> 2024 | P12: =TEXT(B12,"mmm") -> Apr | Q12: =EOMONTH(B12,0) -> 45412 | R12: =TODAY()-B12 -> 905 | S12: =DATEDIF(M12,TODAY(),"Y") -> 3 | T12: =NOW() -> 46313.675
A13: TRX0209 | B13: 45408 | C13: CUST046 | D13: Kathleen Bennett | E13: P008 | F13: Bookshelf | G13: Furniture | H13: 5 | I13: 149.99 | J13: Debit Card | K13: North | L13: Basic | M13: 44830 | N13: 749.95 | O13: =YEAR(B13) -> 2024 | P13: =TEXT(B13,"mmm") -> Apr | Q13: =EOMONTH(B13,0) -> 45412 | R13: =TODAY()-B13 -> 905 | S13: =DATEDIF(M13,TODAY(),"Y") -> 4 | T13: =NOW() -> 46313.675
... A251: TRX0064 | B251: 45758 | C251: CUST031 | D251: Steven Turner | E251: P010 | F251: Keyboard | G251: Electronics | H251: 3 | I251: 89.99 | J251: Debit Card | K251: North | L251: Premium | M251: 44878 | N251: 269.97 | O251: =YEAR(B251) -> 2025 | P251: =TEXT(B251,"mmm") -> Apr | Q251: =EOMONTH(B251,0) -> 45777 | R251: =TODAY()-B251 -> 555 | S251: =DATEDIF(M251,TODAY(),"Y") -> 3 | T251: =NOW() -> 46313.675

Sheet Analysis
A1: 📊 ANALYSIS | Customer, Product & Region Performance
A2: Formula-driven summaries from the 250 transaction records • values update when opened in Excel
A4: CUSTOMER PERFORMANCE | H4: PRODUCT PERFORMANCE
A5: Customer_ID | B5: Customer_Name | C5: Total_Revenue | D5: Transaction_Count | E5: Total_Quantity | F5: Average_Transaction | H5: Product_Name | I5: Units_Sold | J5: Transactions | K5: Total_Revenue
A6: CUST001 | B6: John Smith | C6: =SUMIF(Raw_Data!$C$2:$C$251,A6,Raw_Data!$N$2:$N$251) -> 599.96 | D6: =COUNTIF(Raw_Data!$C$2:$C$251,A6) -> 1 | E6: =SUMIF(Raw_Data!$C$2:$C$251,A6,Raw_Data!$H$2:$H$251) -> 4 | F6: =IFERROR(C6/D6,0) -> 599.96 | H6: Blender | I6: =SUMIF(Raw_Data!$F$2:$F$251,H6,Raw_Data!$H$2:$H$251) -> 87 | J6: =COUNTIF(Raw_Data!$F$2:$F$251,H6) -> 29 | K6: =SUMIF(Raw_Data!$F$2:$F$251,H6,Raw_Data!$N$2:$N$251) -> 5219.13
A7: CUST002 | B7: Emma Wilson | C7: =SUMIF(Raw_Data!$C$2:$C$251,A7,Raw_Data!$N$2:$N$251) -> 1229.88 | D7: =COUNTIF(Raw_Data!$C$2:$C$251,A7) -> 5 | E7: =SUMIF(Raw_Data!$C$2:$C$251,A7,Raw_Data!$H$2:$H$251) -> 12 | F7: =IFERROR(C7/D7,0) -> 245.976 | H7: Bookshelf | I7: =SUMIF(Raw_Data!$F$2:$F$251,H7,Raw_Data!$H$2:$H$251) -> 102 | J7: =COUNTIF(Raw_Data!$F$2:$F$251,H7) -> 35 | K7: =SUMIF(Raw_Data!$F$2:$F$251,H7,Raw_Data!$N$2:$N$251) -> 15298.98
A8: CUST003 | B8: Michael Brown | C8: =SUMIF(Raw_Data!$C$2:$C$251,A8,Raw_Data!$N$2:$N$251) -> 6169.74 | D8: =COUNTIF(Raw_Data!$C$2:$C$251,A8) -> 9 | E8: =SUMIF(Raw_Data!$C$2:$C$251,A8,Raw_Data!$H$2:$H$251) -> 26 | F8: =IFERROR(C8/D8,0) -> 685.52667 | H8: Coffee Maker | I8: =SUMIF(Raw_Data!$F$2:$F$251,H8,Raw_Data!$H$2:$H$251) -> 39 | J8: =COUNTIF(Raw_Data!$F$2:$F$251,H8) -> 14 | K8: =SUMIF(Raw_Data!$F$2:$F$251,H8,Raw_Data!$N$2:$N$251) -> 3119.61
A9: CUST004 | B9: Sarah Davis | C9: =SUMIF(Raw_Data!$C$2:$C$251,A9,Raw_Data!$N$2:$N$251) -> 5499.81 | D9: =COUNTIF(Raw_Data!$C$2:$C$251,A9) -> 5 | E9: =SUMIF(Raw_Data!$C$2:$C$251,A9,Raw_Data!$H$2:$H$251) -> 19 | F9: =IFERROR(C9/D9,0) -> 1099.962 | H9: Desk | I9: =SUMIF(Raw_Data!$F$2:$F$251,H9,Raw_Data!$H$2:$H$251) -> 78 | J9: =COUNTIF(Raw_Data!$F$2:$F$251,H9) -> 26 | K9: =SUMIF(Raw_Data!$F$2:$F$251,H9,Raw_Data!$N$2:$N$251) -> 23399.22
A10: CUST005 | B10: James Johnson | C10: =SUMIF(Raw_Data!$C$2:$C$251,A10,Raw_Data!$N$2:$N$251) -> 179.97 | D10: =COUNTIF(Raw_Data!$C$2:$C$251,A10) -> 1 | E10: =SUMIF(Raw_Data!$C$2:$C$251,A10,Raw_Data!$H$2:$H$251) -> 3 | F10: =IFERROR(C10/D10,0) -> 179.97 | H10: Headphones | I10: =SUMIF(Raw_Data!$F$2:$F$251,H10,Raw_Data!$H$2:$H$251) -> 47 | J10: =COUNTIF(Raw_Data!$F$2:$F$251,H10) -> 16 | K10: =SUMIF(Raw_Data!$F$2:$F$251,H10,Raw_Data!$N$2:$N$251) -> 7049.53
A11: CUST006 | B11: Lisa Anderson | C11: =SUMIF(Raw_Data!$C$2:$C$251,A11,Raw_Data!$N$2:$N$251) -> 2039.8 | D11: =COUNTIF(Raw_Data!$C$2:$C$251,A11) -> 5 | E11: =SUMIF(Raw_Data!$C$2:$C$251,A11,Raw_Data!$H$2:$H$251) -> 20 | F11: =IFERROR(C11/D11,0) -> 407.96 | H11: Keyboard | I11: =SUMIF(Raw_Data!$F$2:$F$251,H11,Raw_Data!$H$2:$H$251) -> 89 | J11: =COUNTIF(Raw_Data!$F$2:$F$251,H11) -> 34 | K11: =SUMIF(Raw_Data!$F$2:$F$251,H11,Raw_Data!$N$2:$N$251) -> 8009.11
A12: CUST007 | B12: David Martinez | C12: =SUMIF(Raw_Data!$C$2:$C$251,A12,Raw_Data!$N$2:$N$251) -> 1809.84 | D12: =COUNTIF(Raw_Data!$C$2:$C$251,A12) -> 6 | E12: =SUMIF(Raw_Data!$C$2:$C$251,A12,Raw_Data!$H$2:$H$251) -> 16 | F12: =IFERROR(C12/D12,0) -> 301.64 | H12: Laptop | I12: =SUMIF(Raw_Data!$F$2:$F$251,H12,Raw_Data!$H$2:$H$251) -> 75 | J12: =COUNTIF(Raw_Data!$F$2:$F$251,H12) -> 24 | K12: =SUMIF(Raw_Data!$F$2:$F$251,H12,Raw_Data!$N$2:$N$251) -> 67499.25
A13: CUST008 | B13: Jennifer Taylor | C13: =SUMIF(Raw_Data!$C$2:$C$251,A13,Raw_Data!$N$2:$N$251) -> 4739.85 | D13: =COUNTIF(Raw_Data!$C$2:$C$251,A13) -> 4 | E13: =SUMIF(Raw_Data!$C$2:$C$251,A13,Raw_Data!$H$2:$H$251) -> 15 | F13: =IFERROR(C13/D13,0) -> 1184.9625 | H13: Monitor | I13: =SUMIF(Raw_Data!$F$2:$F$251,H13,Raw_Data!$H$2:$H$251) -> 88 | J13: =COUNTIF(Raw_Data!$F$2:$F$251,H13) -> 26 | K13: =SUMIF(Raw_Data!$F$2:$F$251,H13,Raw_Data!$N$2:$N$251) -> 21999.12
A14: CUST009 | B14: Robert Thomas | C14: =SUMIF(Raw_Data!$C$2:$C$251,A14,Raw_Data!$N$2:$N$251) -> 3509.9 | D14: =COUNTIF(Raw_Data!$C$2:$C$251,A14) -> 5 | E14: =SUMIF(Raw_Data!$C$2:$C$251,A14,Raw_Data!$H$2:$H$251) -> 10 | F14: =IFERROR(C14/D14,0) -> 701.98 | H14: Office Chair | I14: =SUMIF(Raw_Data!$F$2:$F$251,H14,Raw_Data!$H$2:$H$251) -> 52 | J14: =COUNTIF(Raw_Data!$F$2:$F$251,H14) -> 15 | K14: =SUMIF(Raw_Data!$F$2:$F$251,H14,Raw_Data!$N$2:$N$251) -> 10399.48
A15: CUST010 | B15: Maria Garcia | C15: =SUMIF(Raw_Data!$C$2:$C$251,A15,Raw_Data!$N$2:$N$251) -> 1909.93 | D15: =COUNTIF(Raw_Data!$C$2:$C$251,A15) -> 4 | E15: =SUMIF(Raw_Data!$C$2:$C$251,A15,Raw_Data!$H$2:$H$251) -> 7 | F15: =IFERROR(C15/D15,0) -> 477.4825 | H15: Smartphone | I15: =SUMIF(Raw_Data!$F$2:$F$251,H15,Raw_Data!$H$2:$H$251) -> 96 | J15: =COUNTIF(Raw_Data!$F$2:$F$251,H15) -> 31 | K15: =SUMIF(Raw_Data!$F$2:$F$251,H15,Raw_Data!$N$2:$N$251) -> 67199.04
A16: CUST011 | B16: William White | C16: =SUMIF(Raw_Data!$C$2:$C$251,A16,Raw_Data!$N$2:$N$251) -> 4749.91 | D16: =COUNTIF(Raw_Data!$C$2:$C$251,A16) -> 3 | E16: =SUMIF(Raw_Data!$C$2:$C$251,A16,Raw_Data!$H$2:$H$251) -> 9 | F16: =IFERROR(C16/D16,0) -> 1583.3033
A17: CUST012 | B17: Patricia Moore | C17: =SUMIF(Raw_Data!$C$2:$C$251,A17,Raw_Data!$N$2:$N$251) -> 9799.73 | D17: =COUNTIF(Raw_Data!$C$2:$C$251,A17) -> 8 | E17: =SUMIF(Raw_Data!$C$2:$C$251,A17,Raw_Data!$H$2:$H$251) -> 27 | F17: =IFERROR(C17/D17,0) -> 1224.9662
A18: CUST013 | B18: Joseph Jackson | C18: =SUMIF(Raw_Data!$C$2:$C$251,A18,Raw_Data!$N$2:$N$251) -> 6949.84 | D18: =COUNTIF(Raw_Data!$C$2:$C$251,A18) -> 5 | E18: =SUMIF(Raw_Data!$C$2:$C$251,A18,Raw_Data!$H$2:$H$251) -> 16 | F18: =IFERROR(C18/D18,0) -> 1389.968
A19: CUST014 | B19: Linda Martin | C19: =SUMIF(Raw_Data!$C$2:$C$251,A19,Raw_Data!$N$2:$N$251) -> 1289.9 | D19: =COUNTIF(Raw_Data!$C$2:$C$251,A19) -> 4 | E19: =SUMIF(Raw_Data!$C$2:$C$251,A19,Raw_Data!$H$2:$H$251) -> 10 | F19: =IFERROR(C19/D19,0) -> 322.475 | H19: REGIONAL PERFORMANCE
A20: CUST015 | B20: Richard Lee | C20: =SUMIF(Raw_Data!$C$2:$C$251,A20,Raw_Data!$N$2:$N$251) -> 739.93 | D20: =COUNTIF(Raw_Data!$C$2:$C$251,A20) -> 3 | E20: =SUMIF(Raw_Data!$C$2:$C$251,A20,Raw_Data!$H$2:$H$251) -> 7 | F20: =IFERROR(C20/D20,0) -> 246.64333 | H20: Region | I20: Transactions | J20: Total_Quantity | K20: Total_Revenue
A21: CUST016 | B21: Elizabeth Hall | C21: =SUMIF(Raw_Data!$C$2:$C$251,A21,Raw_Data!$N$2:$N$251) -> 3649.86 | D21: =COUNTIF(Raw_Data!$C$2:$C$251,A21) -> 4 | E21: =SUMIF(Raw_Data!$C$2:$C$251,A21,Raw_Data!$H$2:$H$251) -> 14 | F21: =IFERROR(C21/D21,0) -> 912.465 | H21: Central | I21: =COUNTIF(Raw_Data!$K$2:$K$251,H21) -> 54 | J21: =SUMIF(Raw_Data!$K$2:$K$251,H21,Raw_Data!$H$2:$H$251) -> 166 | K21: =SUMIF(Raw_Data!$K$2:$K$251,H21,Raw_Data!$N$2:$N$251) -> 41288.34
A22: CUST017 | B22: Charles Allen | C22: =SUMIF(Raw_Data!$C$2:$C$251,A22,Raw_Data!$N$2:$N$251) -> 5089.73 | D22: =COUNTIF(Raw_Data!$C$2:$C$251,A22) -> 9 | E22: =SUMIF(Raw_Data!$C$2:$C$251,A22,Raw_Data!$H$2:$H$251) -> 27 | F22: =IFERROR(C22/D22,0) -> 565.52556 | H22: East | I22: =COUNTIF(Raw_Data!$K$2:$K$251,H22) -> 48 | J22: =SUMIF(Raw_Data!$K$2:$K$251,H22,Raw_Data!$H$2:$H$251) -> 161 | K22: =SUMIF(Raw_Data!$K$2:$K$251,H22,Raw_Data!$N$2:$N$251) -> 59288.39
A23: CUST018 | B23: Barbara Young | C23: =SUMIF(Raw_Data!$C$2:$C$251,A23,Raw_Data!$N$2:$N$251) -> 10649.8 | D23: =COUNTIF(Raw_Data!$C$2:$C$251,A23) -> 5 | E23: =SUMIF(Raw_Data!$C$2:$C$251,A23,Raw_Data!$H$2:$H$251) -> 20 | F23: =IFERROR(C23/D23,0) -> 2129.96 | H23: North | I23: =COUNTIF(Raw_Data!$K$2:$K$251,H23) -> 59 | J23: =SUMIF(Raw_Data!$K$2:$K$251,H23,Raw_Data!$H$2:$H$251) -> 169 | K23: =SUMIF(Raw_Data!$K$2:$K$251,H23,Raw_Data!$N$2:$N$251) -> 50808.31
A24: CUST019 | B24: Daniel King | C24: =SUMIF(Raw_Data!$C$2:$C$251,A24,Raw_Data!$N$2:$N$251) -> 7309.8 | D24: =COUNTIF(Raw_Data!$C$2:$C$251,A24) -> 7 | E24: =SUMIF(Raw_Data!$C$2:$C$251,A24,Raw_Data!$H$2:$H$251) -> 20 | F24: =IFERROR(C24/D24,0) -> 1044.2571 | H24: South | I24: =COUNTIF(Raw_Data!$K$2:$K$251,H24) -> 42 | J24: =SUMIF(Raw_Data!$K$2:$K$251,H24,Raw_Data!$H$2:$H$251) -> 125 | K24: =SUMIF(Raw_Data!$K$2:$K$251,H24,Raw_Data!$N$2:$N$251) -> 36398.75
A25: CUST020 | B25: Margaret Wright | C25: =SUMIF(Raw_Data!$C$2:$C$251,A25,Raw_Data!$N$2:$N$251) -> 2099.88 | D25: =COUNTIF(Raw_Data!$C$2:$C$251,A25) -> 4 | E25: =SUMIF(Raw_Data!$C$2:$C$251,A25,Raw_Data!$H$2:$H$251) -> 12 | F25: =IFERROR(C25/D25,0) -> 524.97 | H25: West | I25: =COUNTIF(Raw_Data!$K$2:$K$251,H25) -> 47 | J25: =SUMIF(Raw_Data!$K$2:$K$251,H25,Raw_Data!$H$2:$H$251) -> 132 | K25: =SUMIF(Raw_Data!$K$2:$K$251,H25,Raw_Data!$N$2:$N$251) -> 41408.68
A26: CUST021 | B26: Kevin Scott | C26: =SUMIF(Raw_Data!$C$2:$C$251,A26,Raw_Data!$N$2:$N$251) -> 3259.87 | D26: =COUNTIF(Raw_Data!$C$2:$C$251,A26) -> 6 | E26: =SUMIF(Raw_Data!$C$2:$C$251,A26,Raw_Data!$H$2:$H$251) -> 13 | F26: =IFERROR(C26/D26,0) -> 543.31167
A27: CUST022 | B27: Susan Green | C27: =SUMIF(Raw_Data!$C$2:$C$251,A27,Raw_Data!$N$2:$N$251) -> 1979.89 | D27: =COUNTIF(Raw_Data!$C$2:$C$251,A27) -> 4 | E27: =SUMIF(Raw_Data!$C$2:$C$251,A27,Raw_Data!$H$2:$H$251) -> 11 | F27: =IFERROR(C27/D27,0) -> 494.9725
A28: CUST023 | B28: Paul Baker | C28: =SUMIF(Raw_Data!$C$2:$C$251,A28,Raw_Data!$N$2:$N$251) -> 8309.74 | D28: =COUNTIF(Raw_Data!$C$2:$C$251,A28) -> 8 | E28: =SUMIF(Raw_Data!$C$2:$C$251,A28,Raw_Data!$H$2:$H$251) -> 26 | F28: =IFERROR(C28/D28,0) -> 1038.7175
A29: CUST024 | B29: Dorothy Nelson | C29: =SUMIF(Raw_Data!$C$2:$C$251,A29,Raw_Data!$N$2:$N$251) -> 8269.79 | D29: =COUNTIF(Raw_Data!$C$2:$C$251,A29) -> 6 | E29: =SUMIF(Raw_Data!$C$2:$C$251,A29,Raw_Data!$H$2:$H$251) -> 21 | F29: =IFERROR(C29/D29,0) -> 1378.2983
A30: CUST025 | B30: Mark Carter | C30: =SUMIF(Raw_Data!$C$2:$C$251,A30,Raw_Data!$N$2:$N$251) -> 15659.65 | D30: =COUNTIF(Raw_Data!$C$2:$C$251,A30) -> 12 | E30: =SUMIF(Raw_Data!$C$2:$C$251,A30,Raw_Data!$H$2:$H$251) -> 35 | F30: =IFERROR(C30/D30,0) -> 1304.9708
A31: CUST026 | B31: Karen Hill | C31: =SUMIF(Raw_Data!$C$2:$C$251,A31,Raw_Data!$N$2:$N$251) -> 8009.77 | D31: =COUNTIF(Raw_Data!$C$2:$C$251,A31) -> 8 | E31: =SUMIF(Raw_Data!$C$2:$C$251,A31,Raw_Data!$H$2:$H$251) -> 23 | F31: =IFERROR(C31/D31,0) -> 1001.2212
A32: CUST027 | B32: George Adams | C32: =SUMIF(Raw_Data!$C$2:$C$251,A32,Raw_Data!$N$2:$N$251) -> 3779.93 | D32: =COUNTIF(Raw_Data!$C$2:$C$251,A32) -> 3 | E32: =SUMIF(Raw_Data!$C$2:$C$251,A32,Raw_Data!$H$2:$H$251) -> 7 | F32: =IFERROR(C32/D32,0) -> 1259.9767
A33: CUST028 | B33: Betty Campbell | C33: =SUMIF(Raw_Data!$C$2:$C$251,A33,Raw_Data!$N$2:$N$251) -> 5649.84 | D33: =COUNTIF(Raw_Data!$C$2:$C$251,A33) -> 5 | E33: =SUMIF(Raw_Data!$C$2:$C$251,A33,Raw_Data!$H$2:$H$251) -> 16 | F33: =IFERROR(C33/D33,0) -> 1129.968
A34: CUST029 | B34: Edward Mitchell | C34: =SUMIF(Raw_Data!$C$2:$C$251,A34,Raw_Data!$N$2:$N$251) -> 11919.77 | D34: =COUNTIF(Raw_Data!$C$2:$C$251,A34) -> 6 | E34: =SUMIF(Raw_Data!$C$2:$C$251,A34,Raw_Data!$H$2:$H$251) -> 23 | F34: =IFERROR(C34/D34,0) -> 1986.6283
A35: CUST030 | B35: Helen Roberts | C35: =SUMIF(Raw_Data!$C$2:$C$251,A35,Raw_Data!$N$2:$N$251) -> 6459.79 | D35: =COUNTIF(Raw_Data!$C$2:$C$251,A35) -> 7 | E35: =SUMIF(Raw_Data!$C$2:$C$251,A35,Raw_Data!$H$2:$H$251) -> 21 | F35: =IFERROR(C35/D35,0) -> 922.82714
A36: CUST031 | B36: Steven Turner | C36: =SUMIF(Raw_Data!$C$2:$C$251,A36,Raw_Data!$N$2:$N$251) -> 2649.83 | D36: =COUNTIF(Raw_Data!$C$2:$C$251,A36) -> 6 | E36: =SUMIF(Raw_Data!$C$2:$C$251,A36,Raw_Data!$H$2:$H$251) -> 17 | F36: =IFERROR(C36/D36,0) -> 441.63833
A37: CUST032 | B37: Sandra Phillips | C37: =SUMIF(Raw_Data!$C$2:$C$251,A37,Raw_Data!$N$2:$N$251) -> 6349.83 | D37: =COUNTIF(Raw_Data!$C$2:$C$251,A37) -> 5 | E37: =SUMIF(Raw_Data!$C$2:$C$251,A37,Raw_Data!$H$2:$H$251) -> 17 | F37: =IFERROR(C37/D37,0) -> 1269.966
... A55: CUST050 | B55: Julie Foster | C55: =SUMIF(Raw_Data!$C$2:$C$251,A55,Raw_Data!$N$2:$N$251) -> 239.96 | D55: =COUNTIF(Raw_Data!$C$2:$C$251,A55) -> 1 | E55: =SUMIF(Raw_Data!$C$2:$C$251,A55,Raw_Data!$H$2:$H$251) -> 4 | F55: =IFERROR(C55/D55,0) -> 239.96
A60: MONTHLY PERFORMANCE
A61: Month_Start | B61: Month_Label | C61: Revenue | D61: Transaction_Count | E61: MoM_Growth | F61: Growth_Arrow
A62: 45383 | B62: =TEXT(A62,"mmm yyyy") -> Apr 2024 | C62: =SUMIFS(Raw_Data!$N$2:$N$251,Raw_Data!$B$2:$B$251,">="&A62,Raw_Data!$B$2:$B$251,"<"&EOMONTH(A62,0)+1) -> 20919.33 | D62: =COUNTIFS(Raw_Data!$B$2:$B$251,">="&A62,Raw_Data!$B$2:$B$251,"<"&EOMONTH(A62,0)+1) -> 21 | E62: =0 -> 0 | F62: =IF(E62>0,"▲",IF(E62<0,"▼","●")) -> ●
...

Sheet Visualizations
A1: 📈 VISUALIZATIONS | Sales Performance
A2: Charts are linked to formula-driven summaries on the Analysis sheet.
A39: 📌 Tip: Use Excel's Insert → Slicer / Timeline after converting a summary into a PivotTable if interactive filtering is required.

Sheet Dashboard
A1: 📊 PR. FINAL PROJECT | DATA INTELLIGENCE DASHBOARD
A2: Customer Transactions • Sales Performance • Regional & Product Insights
A4: TOTAL REVENUE | D4: TRANSACTIONS | G4: UNITS SOLD | J4: UNIQUE CUSTOMERS
A5: =SUM(Raw_Data!N2:N251) -> 229192.47 | D5: =COUNTA(Raw_Data!A2:A251) -> 250 | G5: =SUM(Raw_Data!H2:H251) -> 753 | J5: =COUNTA(Analysis!A6:A55) -> 50
A8: KEY INSIGHTS | G8: DATA HEALTH & TIMESTAMP
A9: Top Product by Revenue | B9: =INDEX(Analysis!H6:H15,MATCH(MAX(Analysis!K6:K15),Analysis!K6:K15,0)) -> Laptop | G9: First transaction | H9: =MIN(Raw_Data!B2:B251) -> 45393
A10: Top Region by Revenue | B10: =INDEX(Analysis!H21:H25,MATCH(MAX(Analysis!K21:K25),Analysis!K21:K25,0)) -> East | G10: Latest transaction | H10: =MAX(Raw_Data!B2:B251) -> 45758
A11: Top Customer | B11: =INDEX(Analysis!B6:B55,MATCH(MAX(Analysis!C6:C55),Analysis!C6:C55,0)) -> Mark Carter | G11: Report refreshed at | H11: =NOW() -> 46313.675
A12: Most Frequently Purchased Product | B12: =INDEX(Analysis!H6:H15,MATCH(MAX(Analysis!J6:J15),Analysis!J6:J15,0)) -> Bookshelf | G12: Transaction records | H12: =COUNTA(Raw_Data!A2:A251) -> 250
G31: 🏆 TOP 10 CUSTOMERS BY REVENUE
G32: Rank | H32: Customer Name | I32: Total Revenue | J32: 📖 STORYTELLING PROMPT 1. Compare top products and regions. 2. Check whether monthly revenue rises or falls. 3. Identify high-value customers. 4. Use the scenario planner to discuss discount trade-offs. 5. Turn findings into 2–3 business recommendations.
G33: 1 | H33: =INDEX(Analysis!$B$6:$B$55,MATCH(LARGE(Analysis!$C$6:$C$55,G33),Analysis!$C$6:$C$55,0)) -> Mark Carter | I33: =LARGE(Analysis!$C$6:$C$55,G33) -> 15659.65
G34: 2 | H34: =INDEX(Analysis!$B$6:$B$55,MATCH(LARGE(Analysis!$C$6:$C$55,G34),Analysis!$C$6:$C$55,0)) -> Edward Mitchell | I34: =LARGE(Analysis!$C$6:$C$55,G34) -> 11919.77
G35: 3 | H35: =INDEX(Analysis!$B$6:$B$55,MATCH(LARGE(Analysis!$C$6:$C$55,G35),Analysis!$C$6:$C$55,0)) -> Barbara Young | I35: =LARGE(Analysis!$C$6:$C$55,G35) -> 10649.8
G36: 4 | H36: =INDEX(Analysis!$B$6:$B$55,MATCH(LARGE(Analysis!$C$6:$C$55,G36),Analysis!$C$6:$C$55,0)) -> Patricia Moore | I36: =LARGE(Analysis!$C$6:$C$55,G36) -> 9799.73
G37: 5 | H37: =INDEX(Analysis!$B$6:$B$55,MATCH(LARGE(Analysis!$C$6:$C$55,G37),Analysis!$C$6:$C$55,0)) -> Paul Baker | I37: =LARGE(Analysis!$C$6:$C$55,G37) -> 8309.74
G38: 6 | H38: =INDEX(Analysis!$B$6:$B$55,MATCH(LARGE(Analysis!$C$6:$C$55,G38),Analysis!$C$6:$C$55,0)) -> Dorothy Nelson | I38: =LARGE(Analysis!$C$6:$C$55,G38) -> 8269.79
G39: 7 | H39: =INDEX(Analysis!$B$6:$B$55,MATCH(LARGE(Analysis!$C$6:$C$55,G39),Analysis!$C$6:$C$55,0)) -> Karen Hill | I39: =LARGE(Analysis!$C$6:$C$55,G39) -> 8009.77
G40: 8 | H40: =INDEX(Analysis!$B$6:$B$55,MATCH(LARGE(Analysis!$C$6:$C$55,G40),Analysis!$C$6:$C$55,0)) -> Daniel King | I40: =LARGE(Analysis!$C$6:$C$55,G40) -> 7309.8
G41: 9 | H41: =INDEX(Analysis!$B$6:$B$55,MATCH(LARGE(Analysis!$C$6:$C$55,G41),Analysis!$C$6:$C$55,0)) -> Lawrence Reed | I41: =LARGE(Analysis!$C$6:$C$55,G41) -> 6989.77
G42: 10 | H42: =INDEX(Analysis!$B$6:$B$55,MATCH(LARGE(Analysis!$C$6:$C$55,G42),Analysis!$C$6:$C$55,0)) -> Joseph Jackson | I42: =LARGE(Analysis!$C$6:$C$55,G42) -> 6949.84

Sheet What_If_Analysis
A1: 🧪 WHAT-IF ANALYSIS | Revenue Scenario Planner
A2: Scenario planning is illustrative: dataset has no discount field, so scenarios model a hypothetical discount on current revenue.
A4: BASELINE METRICS | F4: GOAL SEEK GUIDE
A5: Current Total Revenue | B5: =SUM(Raw_Data!N2:N251) -> 229192.47 | F5: Goal | G5: Set B7 to target revenue
A6: Hypothetical Discount | B6: 0.05 | F6: By changing | G6: B6 (discount rate)
A7: Revenue After Discount | B7: =B5*(1-B6) -> 217732.85 | F7: Excel steps | G7: Data → What-If Analysis → Goal Seek
A8: Revenue Reduction | B8: =B5-B7 -> 11459.624 | F8: Target example | G8: Set B7 to 90% of B5
A11: SCENARIO TABLE | F11: SCENARIO MANAGER GUIDE
A12: Scenario | B12: Discount Rate | C12: Estimated Revenue | D12: Revenue Reduction | F12: Create scenarios using B6 as the changing cell. Example scenarios: 0% discount, 5% discount, and 10% discount. In Excel, go to Data → What-If Analysis → Scenario Manager → Add, and save each scenario.
A13: No discount | B13: 0 | C13: =$B$5*(1-B13) -> 229192.47 | D13: =$B$5-C13 -> 0
A14: Low discount | B14: 0.03 | C14: =$B$5*(1-B14) -> 222316.7 | D14: =$B$5-C14 -> 6875.7741
A15: Base discount | B15: 0.05 | C15: =$B$5*(1-B15) -> 217732.85 | D15: =$B$5-C15 -> 11459.624
A16: High discount | B16: 0.1 | C16: =$B$5*(1-B16) -> 206273.22 | D16: =$B$5-C16 -> 22919.247
A17: Very high discount | B17: 0.15 | C17: =$B$5*(1-B17) -> 194813.6 | D17: =$B$5-C17 -> 34378.871

Sheet Insights_Report
A1: 📝 INSIGHTS REPORT | Data Storytelling
A2: A structured report template to document findings from the workbook.
A4: 1. Executive Summary
A5: Summarize total revenue, transaction volume, customer reach, and the main business finding.
A8: 2. Customer Insights
A9: Identify the top customers by revenue. Consider repeat transactions and high-value customer groups.
A12: 3. Product Insights
A13: Compare revenue and units sold by product. Separate most frequently purchased from highest-revenue product.
A16: 4. Regional Insights
A17: Compare regional sales contribution and discuss which regions may need more attention.
A20: 5. Time Trend
A21: Use the monthly revenue chart and growth arrows to describe peaks, declines, and possible seasonality.
... A29: Write 2–3 actionable recommendations supported by figures in the workbook.

Sheet Lists_&_Matching
A1: 🔎 LIST COMPARISON | Repeated Products & Matching Names
A2: Use formulas to identify frequent purchases and match customer names across two lists.
E3: Demo note: List B is a sample subset of List A to demonstrate matching formulas.
A4: PRODUCT FREQUENCY | E4: CUSTOMER NAME MATCHING
A5: Product_Name | B5: Frequency | C5: Most Frequently Purchased? | E5: Customer List A | F5: Customer List B | G5: Match? | H5: Matched Name
A6: Blender | B6: =COUNTIF(Raw_Data!$F$2:$F$251,A6) -> 29 | C6: =IF(B6=MAX($B$6:$B$15),"⭐ Most frequent","") | E6: Arthur Edwards | F6: Arthur Edwards | G6: =IF(COUNTIF($F$6:$F$55,E6)>0,"Match","No match") -> Match | H6: =IFERROR(INDEX($F$6:$F$55,MATCH(E6,$F$6:$F$55,0)),"") -> Arthur Edwards
A7: Bookshelf | B7: =COUNTIF(Raw_Data!$F$2:$F$251,A7) -> 35 | C7: =IF(B7=MAX($B$6:$B$15),"⭐ Most frequent","") -> ⭐ Most frequent | E7: Barbara Young | G7: =IF(COUNTIF($F$6:$F$55,E7)>0,"Match","No match") -> No match | H7: =IFERROR(INDEX($F$6:$F$55,MATCH(E7,$F$6:$F$55,0)),"")
A8: Coffee Maker | B8: =COUNTIF(Raw_Data!$F$2:$F$251,A8) -> 14 | C8: =IF(B8=MAX($B$6:$B$15),"⭐ Most frequent","") | E8: Betty Campbell | F8: Betty Campbell | G8: =IF(COUNTIF($F$6:$F$55,E8)>0,"Match","No match") -> Match | H8: =IFERROR(INDEX($F$6:$F$55,MATCH(E8,$F$6:$F$55,0)),"") -> Betty Campbell
A9: Desk | B9: =COUNTIF(Raw_Data!$F$2:$F$251,A9) -> 26 | C9: =IF(B9=MAX($B$6:$B$15),"⭐ Most frequent","") | E9: Carol Evans | G9: =IF(COUNTIF($F$6:$F$55,E9)>0,"Match","No match") -> No match | H9: =IFERROR(INDEX($F$6:$F$55,MATCH(E9,$F$6:$F$55,0)),"")
A10: Headphones | B10: =COUNTIF(Raw_Data!$F$2:$F$251,A10) -> 16 | C10: =IF(B10=MAX($B$6:$B$15),"⭐ Most frequent","") | E10: Charles Allen | F10: Charles Allen | G10: =IF(COUNTIF($F$6:$F$55,E10)>0,"Match","No match") -> Match | H10: =IFERROR(INDEX($F$6:$F$55,MATCH(E10,$F$6:$F$55,0)),"") -> Charles Allen
A11: Keyboard | B11: =COUNTIF(Raw_Data!$F$2:$F$251,A11) -> 34 | C11: =IF(B11=MAX($B$6:$B$15),"⭐ Most frequent","") | E11: Cynthia Price | G11: =IF(COUNTIF($F$6:$F$55,E11)>0,"Match","No match") -> No match | H11: =IFERROR(INDEX($F$6:$F$55,MATCH(E11,$F$6:$F$55,0)),"")
A12: Laptop | B12: =COUNTIF(Raw_Data!$F$2:$F$251,A12) -> 24 | C12: =IF(B12=MAX($B$6:$B$15),"⭐ Most frequent","") | E12: Daniel King | F12: Daniel King | G12: =IF(COUNTIF($F$6:$F$55,E12)>0,"Match","No match") -> Match | H12: =IFERROR(INDEX($F$6:$F$55,MATCH(E12,$F$6:$F$55,0)),"") -> Daniel King
A13: Monitor | B13: =COUNTIF(Raw_Data!$F$2:$F$251,A13) -> 26 | C13: =IF(B13=MAX($B$6:$B$15),"⭐ Most frequent","") | E13: David Martinez | G13: =IF(COUNTIF($F$6:$F$55,E13)>0,"Match","No match") -> No match | H13: =IFERROR(INDEX($F$6:$F$55,MATCH(E13,$F$6:$F$55,0)),"")
A14: Office Chair | B14: =COUNTIF(Raw_Data!$F$2:$F$251,A14) -> 15 | C14: =IF(B14=MAX($B$6:$B$15),"⭐ Most frequent","") | E14: Dennis Gray | F14: Dennis Gray | G14: =IF(COUNTIF($F$6:$F$55,E14)>0,"Match","No match") -> Match | H14: =IFERROR(INDEX($F$6:$F$55,MATCH(E14,$F$6:$F$55,0)),"") -> Dennis Gray
A15: Smartphone | B15: =COUNTIF(Raw_Data!$F$2:$F$251,A15) -> 31 | C15: =IF(B15=MAX($B$6:$B$15),"⭐ Most frequent","") | E15: Dorothy Nelson | G15: =IF(COUNTIF($F$6:$F$55,E15)>0,"Match","No match") -> No match | H15: =IFERROR(INDEX($F$6:$F$55,MATCH(E15,$F$6:$F$55,0)),"")
E16: Douglas Watson | F16: Douglas Watson | G16: =IF(COUNTIF($F$6:$F$55,E16)>0,"Match","No match") -> Match | H16: =IFERROR(INDEX($F$6:$F$55,MATCH(E16,$F$6:$F$55,0)),"") -> Douglas Watson
E17: Edward Mitchell | G17: =IF(COUNTIF($F$6:$F$55,E17)>0,"Match","No match") -> No match | H17: =IFERROR(INDEX($F$6:$F$55,MATCH(E17,$F$6:$F$55,0)),"")
E18: Elizabeth Hall | F18: Elizabeth Hall | G18: =IF(COUNTIF($F$6:$F$55,E18)>0,"Match","No match") -> Match | H18: =IFERROR(INDEX($F$6:$F$55,MATCH(E18,$F$6:$F$55,0)),"") -> Elizabeth Hall
E19: Emma Wilson | G19: =IF(COUNTIF($F$6:$F$55,E19)>0,"Match","No match") -> No match | H19: =IFERROR(INDEX($F$6:$F$55,MATCH(E19,$F$6:$F$55,0)),"")
E20: Frank Torres | F20: Frank Torres | G20: =IF(COUNTIF($F$6:$F$55,E20)>0,"Match","No match") -> Match | H20: =IFERROR(INDEX($F$6:$F$55,MATCH(E20,$F$6:$F$55,0)),"") -> Frank Torres
E21: George Adams | G21: =IF(COUNTIF($F$6:$F$55,E21)>0,"Match","No match") -> No match | H21: =IFERROR(INDEX($F$6:$F$55,MATCH(E21,$F$6:$F$55,0)),"")
E22: Gerald Murphy | F22: Gerald Murphy | G22: =IF(COUNTIF($F$6:$F$55,E22)>0,"Match","No match") -> Match | H22: =IFERROR(INDEX($F$6:$F$55,MATCH(E22,$F$6:$F$55,0)),"") -> Gerald Murphy
E23: Harry Morgan | G23: =IF(COUNTIF($F$6:$F$55,E23)>0,"Match","No match") -> No match | H23: =IFERROR(INDEX($F$6:$F$55,MATCH(E23,$F$6:$F$55,0)),"")
E24: Helen Roberts | F24: Helen Roberts | G24: =IF(COUNTIF($F$6:$F$55,E24)>0,"Match","No match") -> Match | H24: =IFERROR(INDEX($F$6:$F$55,MATCH(E24,$F$6:$F$55,0)),"") -> Helen Roberts
E25: James Johnson | G25: =IF(COUNTIF($F$6:$F$55,E25)>0,"Match","No match") -> No match | H25: =IFERROR(INDEX($F$6:$F$55,MATCH(E25,$F$6:$F$55,0)),"")
E26: Jennifer Taylor | F26: Jennifer Taylor | G26: =IF(COUNTIF($F$6:$F$55,E26)>0,"Match","No match") -> Match | H26: =IFERROR(INDEX($F$6:$F$55,MATCH(E26,$F$6:$F$55,0)),"") -> Jennifer Taylor
E27: John Smith | G27: =IF(COUNTIF($F$6:$F$55,E27)>0,"Match","No match") -> No match | H27: =IFERROR(INDEX($F$6:$F$55,MATCH(E27,$F$6:$F$55,0)),"")
E28: Joseph Jackson | F28: Joseph Jackson | G28: =IF(COUNTIF($F$6:$F$55,E28)>0,"Match","No match") -> Match | H28: =IFERROR(INDEX($F$6:$F$55,MATCH(E28,$F$6:$F$55,0)),"") -> Joseph Jackson
E29: Julie Foster | G29: =IF(COUNTIF($F$6:$F$55,E29)>0,"Match","No match") -> No match | H29: =IFERROR(INDEX($F$6:$F$55,MATCH(E29,$F$6:$F$55,0)),"")
E30: Karen Hill | F30: Karen Hill | G30: =IF(COUNTIF($F$6:$F$55,E30)>0,"Match","No match") -> Match | H30: =IFERROR(INDEX($F$6:$F$55,MATCH(E30,$F$6:$F$55,0)),"") -> Karen Hill
E31: Kathleen Bennett | G31: =IF(COUNTIF($F$6:$F$55,E31)>0,"Match","No match") -> No match | H31: =IFERROR(INDEX($F$6:$F$55,MATCH(E31,$F$6:$F$55,0)),"")
E32: Kevin Scott | F32: Kevin Scott | G32: =IF(COUNTIF($F$6:$F$55,E32)>0,"Match","No match") -> Match | H32: =IFERROR(INDEX($F$6:$F$55,MATCH(E32,$F$6:$F$55,0)),"") -> Kevin Scott
E33: Lawrence Reed | G33: =IF(COUNTIF($F$6:$F$55,E33)>0,"Match","No match") -> No match | H33: =IFERROR(INDEX($F$6:$F$55,MATCH(E33,$F$6:$F$55,0)),"")
E34: Linda Martin | F34: Linda Martin | G34: =IF(COUNTIF($F$6:$F$55,E34)>0,"Match","No match") -> Match | H34: =IFERROR(INDEX($F$6:$F$55,MATCH(E34,$F$6:$F$55,0)),"") -> Linda Martin
E35: Lisa Anderson | G35: =IF(COUNTIF($F$6:$F$55,E35)>0,"Match","No match") -> No match | H35: =IFERROR(INDEX($F$6:$F$55,MATCH(E35,$F$6:$F$55,0)),"")
E36: Margaret Wright | F36: Margaret Wright | G36: =IF(COUNTIF($F$6:$F$55,E36)>0,"Match","No match") -> Match | H36: =IFERROR(INDEX($F$6:$F$55,MATCH(E36,$F$6:$F$55,0)),"") -> Margaret Wright
E37: Maria Garcia | G37: =IF(COUNTIF($F$6:$F$55,E37)>0,"Match","No match") -> No match | H37: =IFERROR(INDEX($F$6:$F$55,MATCH(E37,$F$6:$F$55,0)),"")
E38: Mark Carter | F38: Mark Carter | G38: =IF(COUNTIF($F$6:$F$55,E38)>0,"Match","No match") -> Match | H38: =IFERROR(INDEX($F$6:$F$55,MATCH(E38,$F$6:$F$55,0)),"") -> Mark Carter
E39: Michael Brown | G39: =IF(COUNTIF($F$6:$F$55,E39)>0,"Match","No match") -> No match | H39: =IFERROR(INDEX($F$6:$F$55,MATCH(E39,$F$6:$F$55,0)),"")
E40: Michelle Rogers | F40: Michelle Rogers | G40: =IF(COUNTIF($F$6:$F$55,E40)>0,"Match","No match") -> Match | H40: =IFERROR(INDEX($F$6:$F$55,MATCH(E40,$F$6:$F$55,0)),"") -> Michelle Rogers
...
